Workbook

Sheet Customers
A1: Customer_ID | B1: Gender | C1: Marital_Status | D1: Applicant_Income | E1: Loan_Amount | F1: Credit_History | G1: Loan_Status | H1: Region
A2: CUST00001 | C2: Single | D2: 113785 | E2: 25750 | F2: Poor | H2: East
A3: CUST00002 | B3: F | C3: Divorced | D3: 166541 | E3: 44384 | F3: Good | G3: Approved | H3: North
A4: CUST00003 | B4: Male | D4: 101441 | E4: 66738 | G4: Rejected | H4: West
A5: CUST00004 | B5: Male | C5: Single | D5: 74681 | E5: 17734 | F5: Poor | H5: North
A6: CUST00005 | B6: F | D6: 96048 | E6: 68433 | F6: Good | G6: Pending | H6: East
A7: CUST00006 | B7: F | C7: Single | D7: 180265 | E7: 44922 | H7: East
A8: CUST00007 | B8: M### | C8: Single | D8: 162868 | E8: 49105 | F8: Good | G8: Pending
A9: CUST00008 | B9: Male | C9: Single | D9: 149136 | E9: 86188 | F9: Unknown | G9: Approved | H9: North
A10: CUST00009 | C10: Divorced | D10: 50991 | E10: 67536 | F10: Good | G10: Rejected | H10: South
A11: CUST00010 | C11: Single | D11: 53161 | E11: 93631 | G11: Rejected | H11: West
A12: CUST00011 | B12: M | C12: Single | D12: 37575 | E12: 83050 | F12: Good | G12: Rejected | H12: West
A13: CUST00012 | B13: Female | C13: Single | D13: 87224 | E13: 75773 | F13: Good
A14: CUST00013 | B14: Male | D14: 186433 | E14: 9561 | F14: Good | G14: Approved | H14: South
A15: CUST00014 | B15: F | C15: Single | D15: 144508 | E15: 87621 | F15: Good | H15: South
A16: CUST00015 | B16: F | C16: Divorced | D16: 164049 | E16: 70080 | F16: Poor | G16: Pending | H16: East
A17: CUST00016 | B17: M | C17: Divorced | D17: 157315 | E17: 50508 | F17: Poor
A18: CUST00017 | B18: Female | C18: Divorced | D18: 191605 | E18: 70766 | F18: Poor | G18: Approved
A19: CUST00018 | B19: F | C19: Divorced | D19: 48112 | E19: 83970 | F19: Good | G19: Approved | H19: South
A20: CUST00019 | B20: Male | C20: Single | D20: 59319 | E20: 51607 | F20: Unknown | G20: Rejected | H20: West
A21: CUST00020 | C21: Single | D21: 160276 | E21: 60133 | F21: Good | G21: Rejected | H21: East
A22: CUST00021 | B22: F | C22: Married | D22: 175649 | E22: 55167 | F22: Good | G22: Approved | H22: East
A23: CUST00022 | C23: Divorced | D23: 35079 | E23: 35937 | F23: Good
A24: CUST00023 | C24: Divorced | D24: 147559 | E24: 61059 | H24: East
A25: CUST00024 | B25: F | D25: 14884 | E25: 19445 | G25: Rejected | H25: South
A26: CUST00025 | B26: Female | D26: 162347 | E26: 33746 | G26: Pending | H26: East
A27: CUST00026 | C27: Married | D27: 128109 | E27: 10392 | F27: Good | G27: Rejected
A28: CUST00027 | B28: Male | C28: Single | D28: 41674 | E28: 61554 | F28: Good | G28: Pending | H28: South
A29: CUST00028 | C29: Married | D29: 111731 | E29: 51328 | F29: Poor | G29: Rejected | H29: North
A30: CUST00029 | D30: 62030 | E30: 64512 | G30: Pending | H30: South
A31: CUST00030 | B31: F | C31: Married | D31: 146702 | E31: 46477 | F31: Unknown | G31: Approved
A32: CUST00031 | B32: F | C32: Divorced | D32: 194176 | E32: 99450 | F32: Poor | G32: Pending | H32: East
A33: CUST00032 | C33: Divorced | D33: 136640 | E33: 77814 | F33: Poor | G33: Approved | H33: South
A34: CUST00033 | B34: M | C34: Divorced | D34: 13295 | E34: 82516 | F34: Poor | G34: Rejected | H34: East
A35: CUST00034 | B35: Female | C35: Divorced | D35: 70360 | E35: 53467 | F35: Unknown | H35: West
A36: CUST00035 | B36: F | D36: 53202 | E36: 52632 | G36: Pending | H36: South
A37: CUST00036 | B37: M | C37: Divorced | D37: 85797 | E37: 30534 | G37: Rejected
A38: CUST00037 | B38: M | C38: Married | D38: 133164 | E38: 16370 | F38: Poor | G38: Approved | H38: East
A39: CUST00038 | B39: Female | C39: Married | D39: 113314 | E39: 26627 | F39: Poor | G39: Approved
A40: CUST00039 | B40: Male | C40: Married | D40: 45742 | E40: 81286 | F40: Poor | G40: Pending | H40: East
...

Sheet customer cleaning sheet
A1: Customer_ID | B1: Gender | C1: Marital_Status | D1: Applicant_Income | E1: Loan_Amount | F1: Credit_History | G1: Loan_Status | H1: Region | I1: RISK FLAG | J1: Pending laon | K1: Top-up-loan
A2: CUST00001 | B2: Not Specified | C2: Single | D2: 113785 | E2: 25750 | F2: Poor | G2: pending | H2: East | I2: =IF(AND(Table1_2[[#This Row],[Credit_History]]="Poor",Table1_2[[#This Row],[Loan_Amount]]<50000),"HIGH RISK","SAFE") -> HIGH RISK | J2: =IF(Table1_2[[#This Row],[Loan_Status]]="pending","follow-up needed","done") -> follow-up needed | K2: =IF(AND(Table1_2[[#This Row],[Applicant_Income]]>70000,Table1_2[[#This Row],[Credit_History]]="good",Table1_2[[#This Row],[Loan_Status]]="approved"),"eligible for top-up","not eligiable") -> not eligiable
A3: CUST00002 | B3: Female | C3: Divorced | D3: 166541 | E3: 44384 | F3: Good | G3: Approved | H3: North | I3: =IF(AND(Table1_2[[#This Row],[Credit_History]]="Poor",Table1_2[[#This Row],[Loan_Amount]]<50000),"HIGH RISK","SAFE") -> SAFE | J3: =IF(Table1_2[[#This Row],[Loan_Status]]="pending","follow-up needed","done") -> done | K3: =IF(AND(Table1_2[[#This Row],[Applicant_Income]]>70000,Table1_2[[#This Row],[Credit_History]]="good",Table1_2[[#This Row],[Loan_Status]]="approved"),"eligible for top-up","not eligiable") -> eligible for top-up
A4: CUST00003 | B4: Male | C4: single | D4: 101441 | E4: 66738 | F4: Poor | G4: Rejected | H4: West | I4: =IF(AND(Table1_2[[#This Row],[Credit_History]]="Poor",Table1_2[[#This Row],[Loan_Amount]]<50000),"HIGH RISK","SAFE") -> SAFE | J4: =IF(Table1_2[[#This Row],[Loan_Status]]="pending","follow-up needed","done") -> done | K4: =IF(AND(Table1_2[[#This Row],[Applicant_Income]]>70000,Table1_2[[#This Row],[Credit_History]]="good",Table1_2[[#This Row],[Loan_Status]]="approved"),"eligible for top-up","not eligiable") -> not eligiable | N4: RISK SUMMARY
A5: CUST00004 | B5: Male | C5: Single | D5: 74681 | E5: 17734 | F5: Poor | G5: pending | H5: North | I5: =IF(AND(Table1_2[[#This Row],[Credit_History]]="Poor",Table1_2[[#This Row],[Loan_Amount]]<50000),"HIGH RISK","SAFE") -> HIGH RISK | J5: =IF(Table1_2[[#This Row],[Loan_Status]]="pending","follow-up needed","done") -> follow-up needed | K5: =IF(AND(Table1_2[[#This Row],[Applicant_Income]]>70000,Table1_2[[#This Row],[Credit_History]]="good",Table1_2[[#This Row],[Loan_Status]]="approved"),"eligible for top-up","not eligiable") -> not eligiable
A6: CUST00005 | B6: Female | C6: single | D6: 96048 | E6: 68433 | F6: Good | G6: Pending | H6: East | I6: =IF(AND(Table1_2[[#This Row],[Credit_History]]="Poor",Table1_2[[#This Row],[Loan_Amount]]<50000),"HIGH RISK","SAFE") -> SAFE | J6: =IF(Table1_2[[#This Row],[Loan_Status]]="pending","follow-up needed","done") -> follow-up needed | K6: =IF(AND(Table1_2[[#This Row],[Applicant_Income]]>70000,Table1_2[[#This Row],[Credit_History]]="good",Table1_2[[#This Row],[Loan_Status]]="approved"),"eligible for top-up","not eligiable") -> not eligiable | N6: SAFE | P6: HIGH RISK | R6: PENDING SUMMERY | U6: follow up needed
A7: CUST00006 | B7: Female | C7: Single | D7: 180265 | E7: 44922 | F7: Poor | G7: pending | H7: East | I7: =IF(AND(Table1_2[[#This Row],[Credit_History]]="Poor",Table1_2[[#This Row],[Loan_Amount]]<50000),"HIGH RISK","SAFE") -> HIGH RISK | J7: =IF(Table1_2[[#This Row],[Loan_Status]]="pending","follow-up needed","done") -> follow-up needed | K7: =IF(AND(Table1_2[[#This Row],[Applicant_Income]]>70000,Table1_2[[#This Row],[Credit_History]]="good",Table1_2[[#This Row],[Loan_Status]]="approved"),"eligible for top-up","not eligiable") -> not eligiable | N7: =COUNTIF(I:I,"SAFE") -> 3182 | P7: =COUNTIF(I:I,"HIGH RISK") -> 1818 | R7: =COUNTIF(J:J,"done") -> 2460 | U7: =COUNTIF(J:J,"follow-up needed") -> 2540
A8: CUST00007 | B8: Male | C8: Single | D8: 162868 | E8: 49105 | F8: Good | G8: Pending | H8: East | I8: =IF(AND(Table1_2[[#This Row],[Credit_History]]="Poor",Table1_2[[#This Row],[Loan_Amount]]<50000),"HIGH RISK","SAFE") -> SAFE | J8: =IF(Table1_2[[#This Row],[Loan_Status]]="pending","follow-up needed","done") -> follow-up needed | K8: =IF(AND(Table1_2[[#This Row],[Applicant_Income]]>70000,Table1_2[[#This Row],[Credit_History]]="good",Table1_2[[#This Row],[Loan_Status]]="approved"),"eligible for top-up","not eligiable") -> not eligiable
A9: CUST00008 | B9: Male | C9: Single | D9: 149136 | E9: 86188 | F9: Poor | G9: Approved | H9: North | I9: =IF(AND(Table1_2[[#This Row],[Credit_History]]="Poor",Table1_2[[#This Row],[Loan_Amount]]<50000),"HIGH RISK","SAFE") -> SAFE | J9: =IF(Table1_2[[#This Row],[Loan_Status]]="pending","follow-up needed","done") -> done | K9: =IF(AND(Table1_2[[#This Row],[Applicant_Income]]>70000,Table1_2[[#This Row],[Credit_History]]="good",Table1_2[[#This Row],[Loan_Status]]="approved"),"eligible for top-up","not eligiable") -> not eligiable
A10: CUST00009 | B10: Not Specified | C10: Divorced | D10: 50991 | E10: 67536 | F10: Good | G10: Rejected | H10: South | I10: =IF(AND(Table1_2[[#This Row],[Credit_History]]="Poor",Table1_2[[#This Row],[Loan_Amount]]<50000),"HIGH RISK","SAFE") -> SAFE | J10: =IF(Table1_2[[#This Row],[Loan_Status]]="pending","follow-up needed","done") -> done | K10: =IF(AND(Table1_2[[#This Row],[Applicant_Income]]>70000,Table1_2[[#This Row],[Credit_History]]="good",Table1_2[[#This Row],[Loan_Status]]="approved"),"eligible for top-up","not eligiable") -> not eligiable
A11: CUST00010 | B11: Not Specified | C11: Single | D11: 53161 | E11: 93631 | F11: Poor | G11: Rejected | H11: West | I11: =IF(AND(Table1_2[[#This Row],[Credit_History]]="Poor",Table1_2[[#This Row],[Loan_Amount]]<50000),"HIGH RISK","SAFE") -> SAFE | J11: =IF(Table1_2[[#This Row],[Loan_Status]]="pending","follow-up needed","done") -> done | K11: =IF(AND(Table1_2[[#This Row],[Applicant_Income]]>70000,Table1_2[[#This Row],[Credit_History]]="good",Table1_2[[#This Row],[Loan_Status]]="approved"),"eligible for top-up","not eligiable") -> not eligiable
A12: CUST00011 | B12: Male | C12: Single | D12: 37575 | E12: 83050 | F12: Good | G12: Rejected | H12: West | I12: =IF(AND(Table1_2[[#This Row],[Credit_History]]="Poor",Table1_2[[#This Row],[Loan_Amount]]<50000),"HIGH RISK","SAFE") -> SAFE | J12: =IF(Table1_2[[#This Row],[Loan_Status]]="pending","follow-up needed","done") -> done | K12: =IF(AND(Table1_2[[#This Row],[Applicant_Income]]>70000,Table1_2[[#This Row],[Credit_History]]="good",Table1_2[[#This Row],[Loan_Status]]="approved"),"eligible for top-up","not eligiable") -> not eligiable
A13: CUST00012 | B13: Female | C13: Single | D13: 87224 | E13: 75773 | F13: Good | G13: pending | H13: East | I13: =IF(AND(Table1_2[[#This Row],[Credit_History]]="Poor",Table1_2[[#This Row],[Loan_Amount]]<50000),"HIGH RISK","SAFE") -> SAFE | J13: =IF(Table1_2[[#This Row],[Loan_Status]]="pending","follow-up needed","done") -> follow-up needed | K13: =IF(AND(Table1_2[[#This Row],[Applicant_Income]]>70000,Table1_2[[#This Row],[Credit_History]]="good",Table1_2[[#This Row],[Loan_Status]]="approved"),"eligible for top-up","not eligiable") -> not eligiable
A14: CUST00013 | B14: Male | C14: single | D14: 186433 | E14: 9561 | F14: Good | G14: Approved | H14: South | I14: =IF(AND(Table1_2[[#This Row],[Credit_History]]="Poor",Table1_2[[#This Row],[Loan_Amount]]<50000),"HIGH RISK","SAFE") -> SAFE | J14: =IF(Table1_2[[#This Row],[Loan_Status]]="pending","follow-up needed","done") -> done | K14: =IF(AND(Table1_2[[#This Row],[Applicant_Income]]>70000,Table1_2[[#This Row],[Credit_History]]="good",Table1_2[[#This Row],[Loan_Status]]="approved"),"eligible for top-up","not eligiable") -> eligible for top-up
A15: CUST00014 | B15: Female | C15: Single | D15: 144508 | E15: 87621 | F15: Good | G15: pending | H15: South | I15: =IF(AND(Table1_2[[#This Row],[Credit_History]]="Poor",Table1_2[[#This Row],[Loan_Amount]]<50000),"HIGH RISK","SAFE") -> SAFE | J15: =IF(Table1_2[[#This Row],[Loan_Status]]="pending","follow-up needed","done") -> follow-up needed | K15: =IF(AND(Table1_2[[#This Row],[Applicant_Income]]>70000,Table1_2[[#This Row],[Credit_History]]="good",Table1_2[[#This Row],[Loan_Status]]="approved"),"eligible for top-up","not eligiable") -> not eligiable
A16: CUST00015 | B16: Female | C16: Divorced | D16: 164049 | E16: 70080 | F16: Poor | G16: Pending | H16: East | I16: =IF(AND(Table1_2[[#This Row],[Credit_History]]="Poor",Table1_2[[#This Row],[Loan_Amount]]<50000),"HIGH RISK","SAFE") -> SAFE | J16: =IF(Table1_2[[#This Row],[Loan_Status]]="pending","follow-up needed","done") -> follow-up needed | K16: =IF(AND(Table1_2[[#This Row],[Applicant_Income]]>70000,Table1_2[[#This Row],[Credit_History]]="good",Table1_2[[#This Row],[Loan_Status]]="approved"),"eligible for top-up","not eligiable") -> not eligiable
A17: CUST00016 | B17: Male | C17: Divorced | D17: 157315 | E17: 50508 | F17: Poor | G17: pending | H17: East | I17: =IF(AND(Table1_2[[#This Row],[Credit_History]]="Poor",Table1_2[[#This Row],[Loan_Amount]]<50000),"HIGH RISK","SAFE") -> SAFE | J17: =IF(Table1_2[[#This Row],[Loan_Status]]="pending","follow-up needed","done") -> follow-up needed | K17: =IF(AND(Table1_2[[#This Row],[Applicant_Income]]>70000,Table1_2[[#This Row],[Credit_History]]="good",Table1_2[[#This Row],[Loan_Status]]="approved"),"eligible for top-up","not eligiable") -> not eligiable
A18: CUST00017 | B18: Female | C18: Divorced | D18: 191605 | E18: 70766 | F18: Poor | G18: Approved | H18: East | I18: =IF(AND(Table1_2[[#This Row],[Credit_History]]="Poor",Table1_2[[#This Row],[Loan_Amount]]<50000),"HIGH RISK","SAFE") -> SAFE | J18: =IF(Table1_2[[#This Row],[Loan_Status]]="pending","follow-up needed","done") -> done | K18: =IF(AND(Table1_2[[#This Row],[Applicant_Income]]>70000,Table1_2[[#This Row],[Credit_History]]="good",Table1_2[[#This Row],[Loan_Status]]="approved"),"eligible for top-up","not eligiable") -> not eligiable
A19: CUST00018 | B19: Female | C19: Divorced | D19: 48112 | E19: 83970 | F19: Good | G19: Approved | H19: South | I19: =IF(AND(Table1_2[[#This Row],[Credit_History]]="Poor",Table1_2[[#This Row],[Loan_Amount]]<50000),"HIGH RISK","SAFE") -> SAFE | J19: =IF(Table1_2[[#This Row],[Loan_Status]]="pending","follow-up needed","done") -> done | K19: =IF(AND(Table1_2[[#This Row],[Applicant_Income]]>70000,Table1_2[[#This Row],[Credit_History]]="good",Table1_2[[#This Row],[Loan_Status]]="approved"),"eligible for top-up","not eligiable") -> not eligiable
... A5001: CUST05000 | B5001: Not Specified | C5001: Single | D5001: 30515 | E5001: 45414 | F5001: Poor | G5001: Rejected | H5001: East | I5001: =IF(AND(Table1_2[[#This Row],[Credit_History]]="Poor",Table1_2[[#This Row],[Loan_Amount]]<50000),"HIGH RISK","SAFE") -> HIGH RISK | J5001: =IF(Table1_2[[#This Row],[Loan_Status]]="pending","follow-up needed","done") -> done | K5001: =IF(AND(Table1_2[[#This Row],[Applicant_Income]]>70000,Table1_2[[#This Row],[Credit_History]]="good",Table1_2[[#This Row],[Loan_Status]]="approved"),"eligible for top-up","not eligiable") -> not eligiable

Sheet Loans
A1: LoanID | B1: CustomerID | C1: LoanType | D1: LoanAmount | E1: InterestRate | F1: TenureMonths | G1: StartDate | H1: Status
A2: LOAN0001 | B2: CUST1288 | C2: Education Loan | D2: 4708414 | E2: 12.75 | F2: 24 | G2: 45127 | H2: Active
A3: LOAN0002 | B3: CUST1791 | C3: Home Loan | D3: 968113 | E3: 8.67 | F3: 24 | G3: 45701 | H3: Active
A4: LOAN0003 | B4: CUST0947 | C4: Education Loan | D4: 866273 | E4: 13.74 | F4: 120 | G4: 44533 | H4: Defaulted
A5: LOAN0004 | B5: CUST0107 | C5: Home Loan | D5: 4214458 | E5: 12.31 | F5: 180 | G5: 45824 | H5: Active
A6: LOAN0005 | B6: CUST0999 | C6: Business Loan | D6: 3589129 | E6: 8.79 | F6: 24 | G6: 45234 | H6: Closed
A7: LOAN0006 | B7: CUST1210 | C7: Business Loan | D7: 2189210 | E7: 9.8 | F7: 120 | G7: 45272 | H7: Active
A8: LOAN0007 | B8: CUST0835 | C8: Business Loan | D8: 2850784 | E8: 12.99 | F8: 36 | G8: 44808 | H8: Closed
A9: LOAN0008 | B9: CUST0575 | C9: Car Loan | D9: 4242692 | E9: 12.15 | F9: 240 | G9: 45764 | H9: Defaulted
A10: LOAN0009 | B10: CUST0467 | C10: Education Loan | D10: 3194739 | E10: 13.6 | F10: 180 | G10: 44329 | H10: Closed
A11: LOAN0010 | B11: CUST1975 | C11: Education Loan | D11: 4971354 | E11: 8.66 | F11: 60 | G11: 45388 | H11: Defaulted
A12: LOAN0011 | B12: CUST1244 | C12: Car Loan | D12: 1567390 | E12: 13.55 | F12: 36 | G12: 45768 | H12: Closed
A13: LOAN0012 | B13: CUST1532 | C13: Personal Loan | D13: 330972 | E13: 13.77 | F13: 36 | G13: 45299 | H13: Active
... A1501: LOAN1500 | B1501: CUST1206 | C1501: Business Loan | D1501: 3109022 | E1501: 9.07 | F1501: 120 | G1501: 44291 | H1501: Defaulted

Sheet Repayments
A1: RepaymentID | B1: LoanID | C1: RepaymentDate | D1: AmountPaid | E1: PaymentMode
A2: REPAY00001 | B2: LOAN0497 | C2: 45667 | D2: 191965 | E2: Online Transfer
A3: REPAY00002 | B3: LOAN0296 | C3: 45604 | D3: 16764 | E3: Cheque
A4: REPAY00003 | B4: LOAN0620 | C4: 45265 | D4: 4819 | E4: UPI
A5: REPAY00004 | B5: LOAN0482 | C5: 45660 | D5: 70143 | E5: Cash
A6: REPAY00005 | B6: LOAN1068 | C6: 45727 | D6: 140235 | E6: UPI
A7: REPAY00006 | B7: LOAN0202 | C7: 45213 | D7: 7760 | E7: Online Transfer
A8: REPAY00007 | B8: LOAN0404 | C8: 44085 | D8: 144408 | E8: Cheque
A9: REPAY00008 | B9: LOAN0879 | C9: 45075 | D9: 193880 | E9: Cash
A10: REPAY00009 | B10: LOAN0095 | C10: 45709 | D10: 126178 | E10: Cheque
A11: REPAY00010 | B11: LOAN0287 | C11: 45582 | D11: 175347 | E11: Online Transfer
A12: REPAY00011 | B12: LOAN1150 | C12: 45762 | D12: 162913 | E12: Online Transfer
A13: REPAY00012 | B13: LOAN0774 | C13: 44471 | D13: 133605 | E13: Cheque
... A3001: REPAY03000 | B3001: LOAN0935 | C3001: 44483 | D3001: 72712 | E3001: Online Transfer

Sheet CreditRisk
A1: CustomerID | B1: CreditScore | C1: RiskLevel | D1: DefaultProbability
A2: CUST0001 | B2: 813 | C2: Low | D2: 0.26
A3: CUST0002 | B3: 664 | C3: Medium | D3: 0.44
A4: CUST0003 | B4: 769 | C4: Low | D4: 0.5
A5: CUST0004 | B5: 382 | C5: High | D5: 0.24
A6: CUST0005 | B6: 574 | C6: Medium | D6: 0.05
A7: CUST0006 | B7: 422 | C7: High | D7: 0.21
A8: CUST0007 | B8: 633 | C8: Medium | D8: 0.3
A9: CUST0008 | B9: 396 | C9: High | D9: 0.12
A10: CUST0009 | B10: 800 | C10: Low | D10: 0.06
A11: CUST0010 | B11: 478 | C11: High | D11: 0.19
A12: CUST0011 | B12: 606 | C12: Medium | D12: 0.32
A13: CUST0012 | B13: 510 | C13: Medium | D13: 0.34
... A2001: CUST2000 | B2001: 707 | C2001: Low | D2001: 0.21

Sheet pyment mode
A3: PaymentMode | B3: Sum of AmountPaid
A4: Cash | B4: 75345221
A5: Cheque | B5: 79868318
A6: Online Transfer | B6: 79214863
A7: UPI | B7: 72872760
A8: Grand Total | B8: 307301162

Sheet loan status report
A3: Loan_Status | B3: Count of Loan_Status
A4: Approved | B4: 1240
A5: Pending | B5: 2540
A6: Rejected | B6: 1220
A7: Grand Total | B7: 5000

Sheet loan type wise chart
A1: loan type wise chart
A3: LoanType | B3: Sum of LoanAmount
A4: Personal Loan | B4: 710314344
A5: Home Loan | B5: 699193432
A6: Education Loan | B6: 746446491
A7: Car Loan | B7: 792939560
A8: Business Loan | B8: 782366796
A9: Grand Total | B9: 3731260623
B13: INSIGHT
A15: TOP 5 | B15: CUSTOMER AMOUNT | C15: CUSTOMER ID | F15: CUSTOMERS FOR HIGH RISK LEVEL
A16: TOP 1 LOAN AMOUNT= | B16: =LARGE(Loans!D2:D1501,1) -> 4996005 | C16: =_xlfn.XLOOKUP(B16,Loans!D2:D1501,Loans!B2:B1501) -> CUST1538
A17: TOP 2 LOAN AMOUNT = | B17: =LARGE(Loans!D2:D1501,2) -> 4995828 | C17: =_xlfn.XLOOKUP(B17,Loans!D2:D1501,Loans!B2:B1501) -> CUST1164 | F17: =COUNTIF(CreditRisk!C2:C2001,"LOW")/COUNTA(CreditRisk!C2:C2001)*100 -> 33.25
A18: TOP 3 LOAN AMOUNT = | B18: =LARGE(Loans!D2:D1501,3) -> 4994613 | C18: =_xlfn.XLOOKUP(B18,Loans!D2:D1501,Loans!B2:B1501) -> CUST1986
A19: TOP 4 LOAN AMOUNT = | B19: =LARGE(Loans!D2:D1501,4) -> 4993295 | C19: =_xlfn.XLOOKUP(B19,Loans!D2:D1501,Loans!B2:B1501) -> CUST0248
A20: TOP 5 LOAN AMOUNT = | B20: =LARGE(Loans!D2:D1501,5) -> 4988164 | C20: =_xlfn.XLOOKUP(B20,Loans!D2:D1501,Loans!B2:B1501) -> CUST0544
